<?xml version="1.0"?>
<!--
  Gazebo ROS ackermann drive plugin demo

  Try sending commands:

    ros2 topic pub /demo/cmd_demo geometry_msgs/msg/Twist '{linear: {x: 1.0}, angular: {z: 0.1}}' -1

  Try listening to odometry:

    ros2 topic echo /demo/odom_demo

  Try listening to odometer reading(linear distance convered):

    ros2 topic echo /demo/distance_demo

  Try listening to TF:

    ros2 run tf2_ros tf2_echo odom_demo chassis

    and other links
-->
<sdf version="1.6">
  <world name="default">
    <include>
      <uri>model://sun</uri>
    </include>

   <gui fullscreen="0">
      <camera name="user_camera">
      <pose>-90 0 80 0 0.82 0</pose>
      </camera>
   </gui>

<model name="ground">
      <pose>0 0 0 0 0 0</pose>
      <static>1</static>
      <link name="ground">
        <collision name="ground_coll">
          <geometry>
            <box>
              <size>83.6 150  0.05</size>
            </box>
          </geometry>
          <surface>
            <contact>
              <ode/>
            </contact>
          </surface>
        </collision>
        <visual name="ground_vis">
          <geometry>
            <box>
              <size>83.6 150  0.05</size>
            </box>
          </geometry>
          <material>
            <script>
              <uri> ./course.material </uri>  <!-- file://course.material -->
              <name>course</name>
            </script>
          </material>
        </visual>
      </link>
    </model>

<model name="prius_hybrid_1">
      <pose>25.88 -17.5 0.04 0 0 1.57</pose>
      <link name="chassis">
        <pose>0 0 0 0 0 1.57</pose>
        <inertial>
          <mass>1326.0</mass>
          <pose>0 -0.266 0.48 0 0 0</pose>
          <inertia>
            <ixx>2581.13354740</ixx>
            <ixy>0.0</ixy>
            <iyy>591.30846112</iyy>
            <ixz>0.0</ixz>
            <iyz>0.0</iyz>
            <izz>2681.95008628</izz>
          </inertia>
        </inertial>

        <visual name="chassis_visual">
          <geometry>
            <mesh>
              <uri>model://prius_hybrid/meshes/Hybrid.obj</uri>
              <scale>0.01 0.01 0.01</scale>
              <submesh>
                <name>Hybrid</name>
                <center>false</center>
              </submesh>
            </mesh>
          </geometry>
        </visual>

        <visual name="interior_visual">
          <geometry>
            <mesh>
              <uri>model://prius_hybrid/meshes/Hybrid.obj</uri>
              <scale>0.01 0.01 0.01</scale>
              <submesh>
                <name>Hybrid_Interior</name>
                <center>false</center>
              </submesh>
            </mesh>
          </geometry>
        </visual>

        <visual name="windows_visual">
          <geometry>
            <mesh>
              <uri>model://prius_hybrid/meshes/Hybrid.obj</uri>
              <scale>0.01 0.01 0.01</scale>
              <submesh>
                <name>Hybrid_Windows</name>
                <center>false</center>
              </submesh>
            </mesh>
          </geometry>
        </visual>

        <collision name="chassis">
          <pose>0.0 0.05 0.625 0 0 0</pose>
          <geometry>
            <box>
              <size>1.7526 2.1 0.95</size>
            </box>
          </geometry>
        </collision>

        <collision name="front_bumper">
          <pose>0.0 -2.0 0.458488 0.0 0 0</pose>
          <geometry>
            <box>
              <size>1.337282 0.48 0.566691</size>
            </box>
          </geometry>
        </collision>

        <collision name="hood">
          <pose>0.0 -1.900842 0.676305 0.341247 0 0</pose>
          <geometry>
            <box>
              <size>1.597968 0.493107 0.265468</size>
            </box>
          </geometry>
        </collision>

        <collision name="windshield">
          <pose>0.0 -0.875105 1.032268 0.335476 0 0</pose>
          <geometry>
            <box>
              <size>1.168381 1.654253 0.272347</size>
            </box>
          </geometry>
        </collision>

        <collision name="top_front">
          <pose>0.0 0.161236 1.386042 0.135030 0 0</pose>
          <geometry>
            <box>
              <size>1.279154 0.625988 0.171868</size>
            </box>
          </geometry>
        </collision>

        <collision name="top_rear">
          <pose>0.0 0.817696 1.360069 -0.068997 0 0</pose>
          <geometry>
            <box>
              <size>1.285130 0.771189 0.226557</size>
            </box>
          </geometry>
        </collision>

        <collision name="rear_window">
          <pose>0.0 1.640531 1.175126 -0.262017 0 0</pose>
          <geometry>
            <box>
              <size>1.267845 1.116344 0.244286</size>
            </box>
          </geometry>
        </collision>

        <collision name="trunk">
          <pose>0.0 1.637059 0.888180 0.0 0 0</pose>
          <geometry>
            <box>
              <size>1.788064 1.138988 0.482746</size>
            </box>
          </geometry>
        </collision>

        <collision name="back_bumper">
          <pose>0.0 2.054454 0.577870 0.0 0 0</pose>
          <geometry>
            <box>
              <size>1.781650 0.512093 0.581427</size>
            </box>
          </geometry>
        </collision>
      </link>

      <link name="steering_wheel">
        <pose>0.627868 0.357734 0.988243 -1.302101 0 1.57</pose>
        <inertial>
          <mass>1.0</mass>
          <inertia>
            <ixx>0.14583300</ixx>
            <ixy>0</ixy>
            <ixz>0</ixz>
            <iyy>0.14583300</iyy>
            <iyz>0</iyz>
            <izz>0.12500000</izz>
          </inertia>
        </inertial>
        <collision name="collision">
          <geometry>
            <cylinder>
              <radius>0.178172</radius>
              <length>0.041845</length>
            </cylinder>
          </geometry>
          <surface>
            <contact>
              <ode>
                <min_depth>0.003</min_depth>
              </ode>
            </contact>
          </surface>
        </collision>
        <visual name="visual">
          <pose>0 0 0 1.302101 0 0</pose>
          <geometry>
            <mesh>
              <uri>model://prius_hybrid/meshes/Hybrid.obj</uri>
              <scale>0.01 0.01 0.01</scale>
              <submesh>
                <name>Steering_Wheel</name>
                <center>true</center>
              </submesh>
            </mesh>
          </geometry>
        </visual>
      </link>

      <link name="front_left_wheel">
        <pose>1.41 0.76 0.3 0 0 1.57</pose>
        <inertial>
          <mass>11</mass>
          <inertia>
            <ixx>0.58631238</ixx>
            <ixy>0.0</ixy>
            <iyy>0.33552910</iyy>
            <ixz>0.0</ixz>
            <iyz>0.0</iyz>
            <izz>0.33552910</izz>
          </inertia>
        </inertial>

        <visual name="visual">
          <pose>0.04 0.0 0.0 0 0 0</pose>
          <geometry>
            <mesh>
              <uri>model://prius_hybrid/meshes/Hybrid.obj</uri>
              <scale>0.01 0.01 0.01</scale>
              <submesh>
                <name>Wheel_Front_Left_</name>
                <center>true</center>
              </submesh>
            </mesh>
          </geometry>
        </visual>

        <collision name="collision">
          <pose>0.0 0.0 0.0 0 1.5707963267948966 0</pose>
          <geometry>
            <sphere>
              <radius>0.31265</radius>
            </sphere>
          </geometry>
          <surface>
            <friction>
              <ode>
                <mu>0.9</mu>
                <mu2>0.9</mu2>
                <slip1>0.0</slip1>
                <slip2>0.0</slip2>
              </ode>
            </friction>
            <contact>
              <ode>
                <min_depth>0.001</min_depth>
                <kp>1e9</kp>
              </ode>
            </contact>
          </surface>

        </collision>
      </link>

      <link name="front_right_wheel">
        <pose>1.41 -0.76 0.3 0 0 1.57</pose>
        <inertial>
          <mass>11</mass>
          <inertia>
            <ixx>0.58631238</ixx>
            <ixy>0.0</ixy>
            <iyy>0.33552910</iyy>
            <ixz>0.0</ixz>
            <iyz>0.0</iyz>
            <izz>0.33552910</izz>
          </inertia>
        </inertial>
        <visual name="visual">
          <pose>-0.04 0.0 0.0 0 0 0</pose>
          <pose>0 0 0.0 0 0 0</pose>
          <geometry>
            <mesh>
              <uri>model://prius_hybrid/meshes/Hybrid.obj</uri>
              <scale>0.01 0.01 0.01</scale>
              <submesh>
                <name>Wheel_Front_Right</name>
                <center>true</center>
              </submesh>
            </mesh>
          </geometry>
        </visual>

        <collision name="collision">
          <pose>0.0 0.0 0.0 0 1.5707963267948966 0</pose>
          <geometry>
            <sphere>
              <radius>0.31265</radius>
            </sphere>
          </geometry>
          <surface>
            <friction>
              <ode>
                <mu>0.9</mu>
                <mu2>0.9</mu2>
                <slip1>0.0</slip1>
                <slip2>0.0</slip2>
              </ode>
            </friction>
            <contact>
              <ode>
                <min_depth>0.001</min_depth>
                <kp>1e9</kp>
              </ode>
            </contact>
          </surface>

        </collision>
      </link>


      <link name="rear_left_wheel">
        <pose>-1.45 0.786 0.3 0 0 1.57</pose>
        <inertial>
          <mass>11</mass>
          <inertia>
            <ixx>0.58631238</ixx>
            <ixy>0.0</ixy>
            <iyy>0.33552910</iyy>
            <ixz>0.0</ixz>
            <iyz>0.0</iyz>
            <izz>0.33552910</izz>
          </inertia>
        </inertial>

        <visual name="visual">
          <pose>0.04 0.0 0.0 0 0 0</pose>
          <geometry>
            <mesh>
              <uri>model://prius_hybrid/meshes/Hybrid.obj</uri>
              <scale>0.01 0.01 0.01</scale>
              <submesh>
                <name>Wheel_Front_Left_</name>
                <center>true</center>
              </submesh>
            </mesh>
          </geometry>
        </visual>

        <collision name="collision">
          <pose>0.0 0.0 0.0 0 1.5707963267948966 0</pose>
          <geometry>
            <sphere>
              <radius>0.31265</radius>
            </sphere>
          </geometry>
          <surface>
            <friction>
              <ode>
                <mu>1.1</mu>
                <mu2>1.1</mu2>
                <slip1>0.0</slip1>
                <slip2>0.0</slip2>
              </ode>
            </friction>
            <contact>
              <ode>
                <min_depth>0.001</min_depth>
                <kp>1e9</kp>
              </ode>
            </contact>
          </surface>

        </collision>
      </link>

      <link name="rear_right_wheel">
        <pose>-1.45 -0.786 0.3 0 0 1.57</pose>
        <inertial>
          <mass>11</mass>
          <inertia>
            <ixx>0.58631238</ixx>
            <ixy>0.0</ixy>
            <iyy>0.33552910</iyy>
            <ixz>0.0</ixz>
            <iyz>0.0</iyz>
            <izz>0.33552910</izz>
          </inertia>
        </inertial>
        <visual name="visual">
          <pose>-0.04 0.0 0.0 0 0 0</pose>
          <geometry>
            <mesh>
              <uri>model://prius_hybrid/meshes/Hybrid.obj</uri>
              <scale>0.01 0.01 0.01</scale>
              <submesh>
                <name>Wheel_Front_Right</name>
                <center>true</center>
              </submesh>
            </mesh>
          </geometry>
        </visual>

        <collision name="collision">
          <pose>0.0 0.0 0.0 0 1.5707963267948966 0</pose>
          <geometry>
            <sphere>
              <radius>0.31265</radius>
            </sphere>
          </geometry>
          <surface>
            <friction>
              <ode>
                <mu>1.1</mu>
                <mu2>1.1</mu2>
                <slip1>0.0</slip1>
                <slip2>0.0</slip2>
              </ode>
            </friction>
            <contact>
              <ode>
                <min_depth>0.001</min_depth>
                <kp>1e9</kp>
              </ode>
            </contact>
          </surface>
        </collision>
      </link>

      <joint type="universal" name="front_left_combined_joint">
        <pose>0 0 0 -0.08726646259971647 0 0</pose>
        <child>front_left_wheel</child>
        <parent>chassis</parent>
        <axis>
          <xyz>0 0 1</xyz>
          <limit>
            <!-- +- 50 degrees -->
            <lower>-0.8727</lower>
            <upper>0.8727</upper>
          </limit>
        </axis>
        <axis2>
          <xyz>1 0 0</xyz>
          <dynamics>
            <friction>18.0474092253</friction>
          </dynamics>
        </axis2>
      </joint>

      <joint type="universal" name="front_right_combined_joint">
        <pose>0 0 0 -0.08726646259971647 0 0</pose>
        <child>front_right_wheel</child>
        <parent>chassis</parent>
        <axis>
          <xyz>0 0 1</xyz>
          <limit>
            <!-- +- 50 degrees -->
            <lower>-0.8727</lower>
            <upper>0.8727</upper>
          </limit>
        </axis>
        <axis2>
          <xyz>1 0 0</xyz>
          <dynamics>
            <friction>18.0474092253</friction>
          </dynamics>
        </axis2>
      </joint>

      <link name="rear_axle">
        <pose>-1.45 0 0.3 0 0 0</pose>
        <inertial>
          <mass>30.0</mass>
          <inertia>
            <ixx>0.08437499999999999</ixx>
            <ixy>0.0</ixy>
            <iyy>4.64581</iyy>
            <ixz>0.0</ixz>
            <iyz>0.0</iyz>
            <izz>4.64581</izz>
          </inertia>
        </inertial>
        <visual name="visual">
          <pose>0.0 0.0 0.0 0 1.5707963267948966 0</pose>
          <geometry>
            <cylinder>
              <length>1.357</length>
              <radius>0.075</radius>
            </cylinder>
          </geometry>
          <material>
            <script>
              <name>Gazebo/Grey</name>
              <uri>file://media/materials/scripts/gazebo.material</uri>
            </script>
          </material>
        </visual>
      </link>

      <joint type="revolute" name="rear_axle_joint">
        <child>rear_axle</child>
        <parent>chassis</parent>
        <axis>
          <xyz>0 1 0</xyz>
          <limit>
            <lower>-0.05089058524173028</lower>
            <upper>0.05089058524173028</upper>
          </limit>
          <dynamics>
            <spring_stiffness>20000.0</spring_stiffness>
            <damping>2000.0</damping>
          </dynamics>
        </axis>
      </joint>
      <joint type="revolute" name="rear_left_wheel_joint">
        <child>rear_left_wheel</child>
        <parent>rear_axle</parent>
        <axis>
          <xyz>1 0 0</xyz>
          <dynamics>
            <friction>12.031606150200002</friction>
          </dynamics>
        </axis>
      </joint>
      <joint type="revolute" name="rear_right_wheel_joint">
        <child>rear_right_wheel</child>
        <parent>rear_axle</parent>
        <axis>
          <xyz>1 0 0</xyz>
          <dynamics>
            <friction>12.031606150200002</friction>
          </dynamics>
        </axis>
      </joint>

      <joint name="steering_joint" type="revolute">
        <pose>-0.002 0 0 0 0 0</pose>
        <parent>chassis</parent>
        <child>steering_wheel</child>
        <axis>
          <xyz>-0.964118 0.000768 0.265556</xyz>
          <limit>
            <lower>-7.85</lower>
            <upper>7.85</upper>
          </limit>
          <dynamics>
            <damping>1.0</damping>
          </dynamics>
          <use_parent_model_frame>true</use_parent_model_frame>
        </axis>
        <physics>
          <ode>
            <cfm_damping>1</cfm_damping>
          </ode>
        </physics>
      </joint>
      <link name="camera_link">
      <pose>2.1 0.7 0 0 0 0</pose>
          <visual name='visual'>
          <geometry>
            <box>
              <size>0.1 0.1 0.1</size>
            </box>
          </geometry>
        </visual>
      </link>

        <link name="camera_rgb_optical_frame">
            <inertial>
                <pose>0 0 0 0 0 0</pose>  <!-- 0.076 0.0 0.093 0 0 0 -->
                <inertia>
                    <ixx>0.001</ixx>
                    <ixy>0.000</ixy>
                    <ixz>0.000</ixz>
                    <iyy>0.001</iyy>
                    <iyz>0.000</iyz>
                    <izz>0.001</izz>
                </inertia>
                <mass>0.035</mass>
            </inertial>

            <pose>1.95 0.8 1.2 0 0.53 0</pose>
            <!--sensor name = "" should change when you use camera more then one-->
            <sensor name="camera1" type="camera">
                <always_on>true</always_on>
                <visualize>true</visualize>
                <update_rate>10</update_rate>
                <camera name="picam">
                    <horizontal_fov>1.3</horizontal_fov>
                    <image>
                        <width>640</width>
                        <height>480</height>
                        <format>R8G8B8</format>
                    </image>
                    <clip>
                        <near>0.03</near>
                        <far>100</far>
                    </clip>
                    <noise>
                        <type>gaussian</type>
                        <!-- Noise is sampled independently per pixel on each frame.
                              That pixel's noise value is added to each of its color
                              channels, which at that point lie in the range [0,1]. -->
                        <mean>0.0</mean>
                        <stddev>0.007</stddev>
                    </noise>
                </camera>
                <plugin name="camera_driver" filename="libgazebo_ros_camera.so">
                    <!-- ros -->
                        <!-- <namespace>test_cam</namespace> not used -->
                        <!-- <remapping>image_raw:=image_demo</remapping> not used  -->
                        <!-- <remapping>camera_info:=camera_info_demo</remapping> not used  -->
                    <!-- /ros -->
                    <!-- camera_name>omit so it defaults to sensor name</camera_name not used -->
                    <!-- frame_name>omit so it defaults to link name</frameName not used -->
                    <!-- <hack_baseline>0.07</hack_baseline>  not used -->
                </plugin>
            </sensor>
        </link>

        <joint name="camera_joint" type="fixed">
            <parent>chassis</parent>
            <child>camera_link</child>
            <pose>0.0 0 0.0 0 0 0</pose>
            <axis>
                <xyz>0 0 1</xyz>
            </axis>
        </joint>

        <joint name="camera_rgb_joint" type="fixed">
            <parent>camera_link</parent>
            <child>camera_rgb_optical_frame</child>
            <pose>0 0 0 0 0 0</pose>  <!-- 0.003 0.011 0.009 0 0 0 -->
            <axis>
                <xyz>0 0 1</xyz>
            </axis>
        </joint>
        
        
      <link name="camera_link2">
       <pose>2 0.7 0.8 0 0 0</pose>
          <visual name='visual'>
          <geometry>
            <box>
              <size>0.1 0.1 0.1</size>
            </box>
          </geometry>
        </visual>
      </link>

        <link name="camera_rgb_optical_frame2">
            <inertial>
                <pose>0 0 0 0 0 0</pose>  <!-- 0.076 0.0 0.093 0 0 0 -->
                <inertia>
                    <ixx>0.001</ixx>
                    <ixy>0.000</ixy>
                    <ixz>0.000</ixz>
                    <iyy>0.001</iyy>
                    <iyz>0.000</iyz>
                    <izz>0.001</izz>
                </inertia>
                <mass>0.035</mass>
            </inertial>

            <pose>2 0.7 0.8 0 0.5 1.57</pose>
            <!--sensor name = "" should change when you use camera more then one-->
            <sensor name="camera2" type="camera">
                <always_on>true</always_on>
                <visualize>true</visualize>
                <update_rate>10</update_rate>
                <camera name="picam">
                    <horizontal_fov>1.085595</horizontal_fov>
                    <image>
                        <width>640</width>
                        <height>480</height>
                        <format>R8G8B8</format>
                    </image>
                    <clip>
                        <near>0.03</near>
                        <far>100</far>
                    </clip>
                    <noise>
                        <type>gaussian</type>
                        <!-- Noise is sampled independently per pixel on each frame.
                              That pixel's noise value is added to each of its color
                              channels, which at that point lie in the range [0,1]. -->
                        <mean>0.0</mean>
                        <stddev>0.007</stddev>
                    </noise>
                </camera>
                <plugin name="camera_driver" filename="libgazebo_ros_camera.so">
                    <!-- ros -->
                        <!-- <namespace>test_cam</namespace> not used -->
                        <!-- <remapping>image_raw:=image_demo</remapping> not used  -->
                        <!-- <remapping>camera_info:=camera_info_demo</remapping> not used  -->
                    <!-- /ros -->
                    <!-- camera_name>omit so it defaults to sensor name</camera_name not used -->
                    <!-- frame_name>omit so it defaults to link name</frameName not used -->
                    <!-- <hack_baseline>0.07</hack_baseline>  not used -->
                </plugin>
            </sensor>
        </link>

        <joint name="camera_joint2" type="fixed">
            <parent>chassis</parent>
            <child>camera_link2</child>
            <pose>0.0 0 0.0 0 0 0</pose>
            <axis>
                <xyz>0 0 1</xyz>
            </axis>
        </joint>

        <joint name="camera_rgb_joint2" type="fixed">
            <parent>camera_link2</parent>
            <child>camera_rgb_optical_frame2</child>
            <pose>0 0 0 0 0 0</pose>  <!-- 0.003 0.011 0.009 0 0 0 -->
            <axis>
                <xyz>0 0 1</xyz>
            </axis>
        </joint>
       
      <plugin name='ackermann_drive' filename='libgazebo_ros_ackermann_drive.so'>

        <ros>
          <namespace>start</namespace>
          <remapping>cmd_vel:=cmd_PR001</remapping>
          <remapping>odom:=odom_demo</remapping>
          <remapping>distance:=distance_demo</remapping>
        </ros>

        <update_rate>100.0</update_rate>

        <!-- wheels -->
        <front_left_joint>front_left_combined_joint</front_left_joint>
        <front_right_joint>front_right_combined_joint</front_right_joint>
        <rear_left_joint>rear_left_wheel_joint</rear_left_joint>
        <rear_right_joint>rear_right_wheel_joint</rear_right_joint>
        <left_steering_joint>front_left_combined_joint</left_steering_joint>
        <right_steering_joint>front_right_combined_joint</right_steering_joint>
        <steering_wheel_joint>steering_joint</steering_wheel_joint>

        <!-- Max absolute steer angle for tyre in radians-->
        <!-- Any cmd_vel angular z greater than this would be capped -->
        <max_steer>0.6458</max_steer>

        <!-- Max absolute steering angle of steering wheel -->
        <max_steering_angle>7.85</max_steering_angle>

        <!-- Max absolute linear speed in m/s -->
        <max_speed>6</max_speed>

        <!-- PID tuning -->
        <left_steering_pid_gain>1500 0 1</left_steering_pid_gain>
        <left_steering_i_range>0 0</left_steering_i_range>
        <right_steering_pid_gain>1500 0 1</right_steering_pid_gain>
        <right_steering_i_range>0 0</right_steering_i_range>
        <linear_velocity_pid_gain>1000 0 1</linear_velocity_pid_gain>
        <linear_velocity_i_range>0 0</linear_velocity_i_range>

        <!-- output -->
        <publish_odom>true</publish_odom>
        <publish_odom_tf>true</publish_odom_tf>
        <publish_wheel_tf>true</publish_wheel_tf>
        <publish_distance>true</publish_distance>

        <odometry_frame>odom_demo</odometry_frame>
        <robot_base_frame>chassis</robot_base_frame>

      </plugin>
<link name="hokuyo_link">
            <pose>2.1 0 0.8 0 0 0</pose>
            <inertial>
               <inertia>
                  <ixx>1e-6</ixx>
                  <ixy>0</ixy>
                  <ixz>0</ixz>
                  <iyy>1e-6</iyy>
            <iyz>0</iyz>
            <izz>1e-6</izz>
         </inertia>
         <mass>1e-5</mass>
      </inertial>
      <collision name ="collision">
         <pose>0 0 0.5 0 0 0</pose>
         <geometry>
            <box>
               <size>0.1 0.1 0.1</size>
            </box> 
         </geometry>
      </collision>
      <visual name="visual">
         <geometry>
            <mesh>
               <uri>model://hokuyo/meshes/hokuyo.dae</uri>
            </mesh>
         </geometry>
      </visual>
      <sensor name="laser" type="gpu_ray">
         <pose>0.01 0 0.0175 0 -0 0</pose>
          <ray>
                 <scan>
                     <horizontal>
                           <samples>320</samples>
                          <resolution>5</resolution>
                          <min_angle>-0.50</min_angle>
                          <max_angle>0.50</max_angle>
                      </horizontal>
                   </scan>
                 <range>
                      <min>1</min>
                      <max>10</max>
                 </range>
              </ray>
         <plugin name="laser" filename="libgazebo_ros_ray_sensor.so">
            <ros>
               <remapping>~/out:=scan</remapping>
            </ros>
            
            <frame_name>laser_Frame</frame_name>
            <output_type>sensor_msgs/LaserScan</output_type>
         </plugin>
         <always_on>1</always_on>
         <update_rate>5</update_rate>
         <visualize>1</visualize>
      </sensor>
   </link>
   <joint name="hokuyo_joint" type="revolute">
      <parent>chassis</parent>
      <child>hokuyo_link</child>
      <axis>
         <xyz>0 1 0</xyz>
         <limit>
            <upper>0</upper>
            <lower>0</lower>
         </limit>
      </axis>
   </joint>   
   
    </model>

<!--          
from now on, under lines are for other prius_hybird car!!

from now on, under lines are for other prius_hybird car!!

from now on, under lines are for other prius_hybird car!!

from now on, under lines are for other prius_hybird car!!
-->

    <model name="prius_hybrid">
      <pose>29.97 -17.5 0.04 0 0 1.57</pose>
      <link name="chassis">
        <pose>0 0 0 0 0 1.57</pose>
        <inertial>
          <mass>1326.0</mass>
          <pose>0 -0.266 0.48 0 0 0</pose>
          <inertia>
            <ixx>2581.13354740</ixx>
            <ixy>0.0</ixy>
            <iyy>591.30846112</iyy>
            <ixz>0.0</ixz>
            <iyz>0.0</iyz>
            <izz>2681.95008628</izz>
          </inertia>
        </inertial>

        <visual name="chassis_visual">
          <geometry>
            <mesh>
              <uri>model://prius_hybrid/meshes/Hybrid.obj</uri>
              <scale>0.01 0.01 0.01</scale>
              <submesh>
                <name>Hybrid</name>
                <center>false</center>
              </submesh>
            </mesh>
          </geometry>
        </visual>

        <visual name="interior_visual">
          <geometry>
            <mesh>
              <uri>model://prius_hybrid/meshes/Hybrid.obj</uri>
              <scale>0.01 0.01 0.01</scale>
              <submesh>
                <name>Hybrid_Interior</name>
                <center>false</center>
              </submesh>
            </mesh>
          </geometry>
        </visual>

        <visual name="windows_visual">
          <geometry>
            <mesh>
              <uri>model://prius_hybrid/meshes/Hybrid.obj</uri>
              <scale>0.01 0.01 0.01</scale>
              <submesh>
                <name>Hybrid_Windows</name>
                <center>false</center>
              </submesh>
            </mesh>
          </geometry>
        </visual>

        <collision name="chassis">
          <pose>0.0 0.05 0.625 0 0 0</pose>
          <geometry>
            <box>
              <size>1.7526 2.1 0.95</size>
            </box>
          </geometry>
        </collision>

        <collision name="front_bumper">
          <pose>0.0 -2.0 0.458488 0.0 0 0</pose>
          <geometry>
            <box>
              <size>1.337282 0.48 0.566691</size>
            </box>
          </geometry>
        </collision>

        <collision name="hood">
          <pose>0.0 -1.900842 0.676305 0.341247 0 0</pose>
          <geometry>
            <box>
              <size>1.597968 0.493107 0.265468</size>
            </box>
          </geometry>
        </collision>

        <collision name="windshield">
          <pose>0.0 -0.875105 1.032268 0.335476 0 0</pose>
          <geometry>
            <box>
              <size>1.168381 1.654253 0.272347</size>
            </box>
          </geometry>
        </collision>

        <collision name="top_front">
          <pose>0.0 0.161236 1.386042 0.135030 0 0</pose>
          <geometry>
            <box>
              <size>1.279154 0.625988 0.171868</size>
            </box>
          </geometry>
        </collision>

        <collision name="top_rear">
          <pose>0.0 0.817696 1.360069 -0.068997 0 0</pose>
          <geometry>
            <box>
              <size>1.285130 0.771189 0.226557</size>
            </box>
          </geometry>
        </collision>

        <collision name="rear_window">
          <pose>0.0 1.640531 1.175126 -0.262017 0 0</pose>
          <geometry>
            <box>
              <size>1.267845 1.116344 0.244286</size>
            </box>
          </geometry>
        </collision>

        <collision name="trunk">
          <pose>0.0 1.637059 0.888180 0.0 0 0</pose>
          <geometry>
            <box>
              <size>1.788064 1.138988 0.482746</size>
            </box>
          </geometry>
        </collision>

        <collision name="back_bumper">
          <pose>0.0 2.054454 0.577870 0.0 0 0</pose>
          <geometry>
            <box>
              <size>1.781650 0.512093 0.581427</size>
            </box>
          </geometry>
        </collision>
      </link>

      <link name="steering_wheel">
        <pose>0.627868 0.357734 0.988243 -1.302101 0 1.57</pose>
        <inertial>
          <mass>1.0</mass>
          <inertia>
            <ixx>0.14583300</ixx>
            <ixy>0</ixy>
            <ixz>0</ixz>
            <iyy>0.14583300</iyy>
            <iyz>0</iyz>
            <izz>0.12500000</izz>
          </inertia>
        </inertial>
        <collision name="collision">
          <geometry>
            <cylinder>
              <radius>0.178172</radius>
              <length>0.041845</length>
            </cylinder>
          </geometry>
          <surface>
            <contact>
              <ode>
                <min_depth>0.003</min_depth>
              </ode>
            </contact>
          </surface>
        </collision>
        <visual name="visual">
          <pose>0 0 0 1.302101 0 0</pose>
          <geometry>
            <mesh>
              <uri>model://prius_hybrid/meshes/Hybrid.obj</uri>
              <scale>0.01 0.01 0.01</scale>
              <submesh>
                <name>Steering_Wheel</name>
                <center>true</center>
              </submesh>
            </mesh>
          </geometry>
        </visual>
      </link>

      <link name="front_left_wheel">
        <pose>1.41 0.76 0.3 0 0 1.57</pose>
        <inertial>
          <mass>11</mass>
          <inertia>
            <ixx>0.58631238</ixx>
            <ixy>0.0</ixy>
            <iyy>0.33552910</iyy>
            <ixz>0.0</ixz>
            <iyz>0.0</iyz>
            <izz>0.33552910</izz>
          </inertia>
        </inertial>
        <visual name="visual">
          <pose>0.04 0.0 0.0 0 0 0</pose>
          <geometry>
            <mesh>
              <uri>model://prius_hybrid/meshes/Hybrid.obj</uri>
              <scale>0.01 0.01 0.01</scale>
              <submesh>
                <name>Wheel_Front_Left_</name>
                <center>true</center>
              </submesh>
            </mesh>
          </geometry>
        </visual>

        <collision name="collision">
          <pose>0.0 0.0 0.0 0 1.5707963267948966 0</pose>
          <geometry>
            <sphere>
              <radius>0.31265</radius>
            </sphere>
          </geometry>
          <surface>
            <friction>
              <ode>
                <mu>0.9</mu>
                <mu2>0.9</mu2>
                <slip1>0.0</slip1>
                <slip2>0.0</slip2>
              </ode>
            </friction>
            <contact>
              <ode>
                <min_depth>0.001</min_depth>
                <kp>1e9</kp>
              </ode>
            </contact>
          </surface>

        </collision>
      </link>

      <link name="front_right_wheel">
        <pose>1.41 -0.76 0.3 0 0 1.57</pose>
        <inertial>
          <mass>11</mass>
          <inertia>
            <ixx>0.58631238</ixx>
            <ixy>0.0</ixy>
            <iyy>0.33552910</iyy>
            <ixz>0.0</ixz>
            <iyz>0.0</iyz>
            <izz>0.33552910</izz>
          </inertia>
        </inertial>
        <visual name="visual">
          <pose>-0.04 0.0 0.0 0 0 0</pose>
          <pose>0 0 0.0 0 0 0</pose>
          <geometry>
            <mesh>
              <uri>model://prius_hybrid/meshes/Hybrid.obj</uri>
              <scale>0.01 0.01 0.01</scale>
              <submesh>
                <name>Wheel_Front_Right</name>
                <center>true</center>
              </submesh>
            </mesh>
          </geometry>
        </visual>

        <collision name="collision">
          <pose>0.0 0.0 0.0 0 1.5707963267948966 0</pose>
          <geometry>
            <sphere>
              <radius>0.31265</radius>
            </sphere>
          </geometry>
          <surface>
            <friction>
              <ode>
                <mu>0.9</mu>
                <mu2>0.9</mu2>
                <slip1>0.0</slip1>
                <slip2>0.0</slip2>
              </ode>
            </friction>
            <contact>
              <ode>
                <min_depth>0.001</min_depth>
                <kp>1e9</kp>
              </ode>
            </contact>
          </surface>

        </collision>
      </link>


      <link name="rear_left_wheel">
        <pose>-1.45 0.786 0.3 0 0 1.57</pose>
        <inertial>
          <mass>11</mass>
          <inertia>
            <ixx>0.58631238</ixx>
            <ixy>0.0</ixy>
            <iyy>0.33552910</iyy>
            <ixz>0.0</ixz>
            <iyz>0.0</iyz>
            <izz>0.33552910</izz>
          </inertia>
        </inertial>

        <visual name="visual">
          <pose>0.04 0.0 0.0 0 0 0</pose>
          <geometry>
            <mesh>
              <uri>model://prius_hybrid/meshes/Hybrid.obj</uri>
              <scale>0.01 0.01 0.01</scale>
              <submesh>
                <name>Wheel_Front_Left_</name>
                <center>true</center>
              </submesh>
            </mesh>
          </geometry>
        </visual>

        <collision name="collision">
          <pose>0.0 0.0 0.0 0 1.5707963267948966 0</pose>
          <geometry>
            <sphere>
              <radius>0.31265</radius>
            </sphere>
          </geometry>
          <surface>
            <friction>
              <ode>
                <mu>1.1</mu>
                <mu2>1.1</mu2>
                <slip1>0.0</slip1>
                <slip2>0.0</slip2>
              </ode>
            </friction>
            <contact>
              <ode>
                <min_depth>0.001</min_depth>
                <kp>1e9</kp>
              </ode>
            </contact>
          </surface>

        </collision>
      </link>

      <link name="rear_right_wheel">
        <pose>-1.45 -0.786 0.3 0 0 1.57</pose>
        <inertial>
          <mass>11</mass>
          <inertia>
            <ixx>0.58631238</ixx>
            <ixy>0.0</ixy>
            <iyy>0.33552910</iyy>
            <ixz>0.0</ixz>
            <iyz>0.0</iyz>
            <izz>0.33552910</izz>
          </inertia>
        </inertial>
        <visual name="visual">
          <pose>-0.04 0.0 0.0 0 0 0</pose>
          <geometry>
            <mesh>
              <uri>model://prius_hybrid/meshes/Hybrid.obj</uri>
              <scale>0.01 0.01 0.01</scale>
              <submesh>
                <name>Wheel_Front_Right</name>
                <center>true</center>
              </submesh>
            </mesh>
          </geometry>
        </visual>

        <collision name="collision">
          <pose>0.0 0.0 0.0 0 1.5707963267948966 0</pose>
          <geometry>
            <sphere>
              <radius>0.31265</radius>
            </sphere>
          </geometry>
          <surface>
            <friction>
              <ode>
                <mu>1.1</mu>
                <mu2>1.1</mu2>
                <slip1>0.0</slip1>
                <slip2>0.0</slip2>
              </ode>
            </friction>
            <contact>
              <ode>
                <min_depth>0.001</min_depth>
                <kp>1e9</kp>
              </ode>
            </contact>
          </surface>
        </collision>
      </link>

      <joint type="universal" name="front_left_combined_joint">
        <pose>0 0 0 -0.08726646259971647 0 0</pose>
        <child>front_left_wheel</child>
        <parent>chassis</parent>
        <axis>
          <xyz>0 0 1</xyz>
          <limit>
            <!-- +- 50 degrees -->
            <lower>-0.8727</lower>
            <upper>0.8727</upper>
          </limit>
        </axis>
        <axis2>
          <xyz>1 0 0</xyz>
          <dynamics>
            <friction>18.0474092253</friction>
          </dynamics>
        </axis2>
      </joint>

      <joint type="universal" name="front_right_combined_joint">
        <pose>0 0 0 -0.08726646259971647 0 0</pose>
        <child>front_right_wheel</child>
        <parent>chassis</parent>
        <axis>
          <xyz>0 0 1</xyz>
          <limit>
            <!-- +- 50 degrees -->
            <lower>-0.8727</lower>
            <upper>0.8727</upper>
          </limit>
        </axis>
        <axis2>
          <xyz>1 0 0</xyz>
          <dynamics>
            <friction>18.0474092253</friction>
          </dynamics>
        </axis2>
      </joint>

      <link name="rear_axle">
        <pose>-1.45 0 0.3 0 0 0</pose>
        <inertial>
          <mass>30.0</mass>
          <inertia>
            <ixx>0.08437499999999999</ixx>
            <ixy>0.0</ixy>
            <iyy>4.64581</iyy>
            <ixz>0.0</ixz>
            <iyz>0.0</iyz>
            <izz>4.64581</izz>
          </inertia>
        </inertial>
        <visual name="visual">
          <pose>0.0 0.0 0.0 0 1.5707963267948966 0</pose>
          <geometry>
            <cylinder>
              <length>1.357</length>
              <radius>0.075</radius>
            </cylinder>
          </geometry>
          <material>
            <script>
              <name>Gazebo/Grey</name>
              <uri>file://media/materials/scripts/gazebo.material</uri>
            </script>
          </material>
        </visual>
      </link>

      <joint type="revolute" name="rear_axle_joint">
        <child>rear_axle</child>
        <parent>chassis</parent>
        <axis>
          <xyz>0 1 0</xyz>
          <limit>
            <lower>-0.05089058524173028</lower>
            <upper>0.05089058524173028</upper>
          </limit>
          <dynamics>
            <spring_stiffness>20000.0</spring_stiffness>
            <damping>2000.0</damping>
          </dynamics>
        </axis>
      </joint>
      <joint type="revolute" name="rear_left_wheel_joint">
        <child>rear_left_wheel</child>
        <parent>rear_axle</parent>
        <axis>
          <xyz>1 0 0</xyz>
          <dynamics>
            <friction>12.031606150200002</friction>
          </dynamics>
        </axis>
      </joint>
      <joint type="revolute" name="rear_right_wheel_joint">
        <child>rear_right_wheel</child>
        <parent>rear_axle</parent>
        <axis>
          <xyz>1 0 0</xyz>
          <dynamics>
            <friction>12.031606150200002</friction>
          </dynamics>
        </axis>
      </joint>

      <joint name="steering_joint" type="revolute">
        <pose>-0.002 0 0 0 0 0</pose>
        <parent>chassis</parent>
        <child>steering_wheel</child>
        <axis>
          <xyz>-0.964118 0.000768 0.265556</xyz>
          <limit>
            <lower>-7.85</lower>
            <upper>7.85</upper>
          </limit>
          <dynamics>
            <damping>1.0</damping>
          </dynamics>
          <use_parent_model_frame>true</use_parent_model_frame>
        </axis>
        <physics>
          <ode>
            <cfm_damping>1</cfm_damping>
          </ode>
        </physics>
      </joint>


           <link name="camera_link3">
       <pose>2 -0.7 0.8 0 0 0</pose>
          <visual name='visual'>
          <geometry>
            <box>
              <size>0.1 0.1 0.1</size>
            </box>
          </geometry>
        </visual>
      </link>

        <link name="camera_rgb_optical_frame3">
            <inertial>
                <pose>0 0 0 0 0 0</pose>  <!-- 0.076 0.0 0.093 0 0 0 -->
                <inertia>
                    <ixx>0.001</ixx>
                    <ixy>0.000</ixy>
                    <ixz>0.000</ixz>
                    <iyy>0.001</iyy>
                    <iyz>0.000</iyz>
                    <izz>0.001</izz>
                </inertia>
                <mass>0.035</mass>
            </inertial>

            <pose>2.0 -0.1 1.2 0 0.51 0</pose>
            <!--sensor name = "" should change when you use camera more then one-->
            <sensor name="camera3" type="camera">
                <always_on>true</always_on>
                <visualize>true</visualize>
                <update_rate>10</update_rate>
                <camera name="picam">
                    <horizontal_fov>1.085595</horizontal_fov>
                    <image>
                        <width>640</width>
                        <height>480</height>
                        <format>R8G8B8</format>
                    </image>
                    <clip>
                        <near>0.03</near>
                        <far>100</far>
                    </clip>
                    <noise>
                        <type>gaussian</type>
                        <!-- Noise is sampled independently per pixel on each frame.
                              That pixel's noise value is added to each of its color
                              channels, which at that point lie in the range [0,1]. -->
                        <mean>0.0</mean>
                        <stddev>0.007</stddev>
                    </noise>
                </camera>
                <plugin name="camera_driver" filename="libgazebo_ros_camera.so">
                    <!-- ros -->
                        <!-- <namespace>test_cam</namespace> not used -->
                        <!-- <remapping>image_raw:=image_demo</remapping> not used  -->
                        <!-- <remapping>camera_info:=camera_info_demo</remapping> not used  -->
                    <!-- /ros -->
                    <!-- camera_name>omit so it defaults to sensor name</camera_name not used -->
                    <!-- frame_name>omit so it defaults to link name</frameName not used -->
                    <!-- <hack_baseline>0.07</hack_baseline>  not used -->
                </plugin>
            </sensor>
        </link>

        <joint name="camera_joint3" type="fixed">
            <parent>chassis</parent>
            <child>camera_link3</child>
            <pose>0.0 0 0.0 0 0 0</pose>
            <axis>
                <xyz>0 0 1</xyz>
            </axis>
        </joint>

        <joint name="camera_rgb_joint3" type="fixed">
            <parent>camera_link3</parent>
            <child>camera_rgb_optical_frame3</child>
            <pose>0 0 0 0 0 0</pose>  <!-- 0.003 0.011 0.009 0 0 0 -->
            <axis>
                <xyz>0 0 1</xyz>
            </axis>
        </joint>

      
      
            <link name="camera_link4">
       <pose>2 -0.7 0.8 0 0 0</pose>
          <visual name='visual'>
          <geometry>
            <box>
              <size>0.1 0.1 0.1</size>
            </box>
          </geometry>
        </visual>
      </link>

        <link name="camera_rgb_optical_frame4">
            <inertial>
                <pose>0 0 0 0 0 0</pose>  <!-- 0.076 0.0 0.093 0 0 0 -->
                <inertia>
                    <ixx>0.001</ixx>
                    <ixy>0.000</ixy>
                    <ixz>0.000</ixz>
                    <iyy>0.001</iyy>
                    <iyz>0.000</iyz>
                    <izz>0.001</izz>
                </inertia>
                <mass>0.035</mass>
            </inertial>

            <pose>2 -0.7 0.8 0 0.43 -1.57</pose>
            <!--sensor name = "" should change when you use camera more then one-->
            <sensor name="camera4" type="camera">
                <always_on>true</always_on>
                <visualize>true</visualize>
                <update_rate>10</update_rate>
                <camera name="picam">
                    <horizontal_fov>1.085595</horizontal_fov>
                    <image>
                        <width>640</width>
                        <height>480</height>
                        <format>R8G8B8</format>
                    </image>
                    <clip>
                        <near>0.03</near>                         
                        <far>100</far>
                    </clip>
                    <noise>
                        <type>gaussian</type>
                        <!-- Noise is sampled independently per pixel on each frame.
                              That pixel's noise value is added to each of its color
                              channels, which at that point lie in the range [0,1]. -->
                        <mean>0.0</mean>
                        <stddev>0.007</stddev>
                    </noise>
                </camera>
                <plugin name="camera_driver" filename="libgazebo_ros_camera.so">
                    <!-- ros -->
                        <!-- <namespace>test_cam</namespace> not used -->
                        <!-- <remapping>image_raw:=image_demo</remapping> not used  -->
                        <!-- <remapping>camera_info:=camera_info_demo</remapping> not used  -->
                    <!-- /ros -->
                    <!-- camera_name>omit so it defaults to sensor name</camera_name not used -->
                    <!-- frame_name>omit so it defaults to link name</frameName not used -->
                    <!-- <hack_baseline>0.07</hack_baseline>  not used -->
                </plugin>
            </sensor>
        </link>

        <joint name="camera_joint4" type="fixed">
            <parent>chassis</parent>
            <child>camera_link4</child>
            <pose>0.0 0 0.0 0 0 0</pose>
            <axis>
                <xyz>0 0 1</xyz>
            </axis>
        </joint>

        <joint name="camera_rgb_joint4" type="fixed">
            <parent>camera_link4</parent>
            <child>camera_rgb_optical_frame4</child>
            <pose>0 0 0 0 0 0</pose>  <!-- 0.003 0.011 0.009 0 0 0 -->
            <axis>
                <xyz>0 0 1</xyz>
            </axis>
        </joint>

      <plugin name='ackermann_drive' filename='libgazebo_ros_ackermann_drive.so'>

        <ros>
          <namespace>start</namespace>
          <remapping>cmd_vel:=cmd_PR002</remapping>
          <remapping>odom:=odom_demo</remapping>
          <remapping>distance:=distance_demo</remapping>
        </ros>

        <update_rate>100.0</update_rate>

        <!-- wheels -->
        <front_left_joint>front_left_combined_joint</front_left_joint>
        <front_right_joint>front_right_combined_joint</front_right_joint>
        <rear_left_joint>rear_left_wheel_joint</rear_left_joint>
        <rear_right_joint>rear_right_wheel_joint</rear_right_joint>
        <left_steering_joint>front_left_combined_joint</left_steering_joint>
        <right_steering_joint>front_right_combined_joint</right_steering_joint>
        <steering_wheel_joint>steering_joint</steering_wheel_joint>

        <!-- Max absolute steer angle for tyre in radians-->
        <!-- Any cmd_vel angular z greater than this would be capped -->
        <max_steer>0.6458</max_steer>

        <!-- Max absolute steering angle of steering wheel -->
        <max_steering_angle>7.85</max_steering_angle>

        <!-- Max absolute linear speed in m/s -->
        <max_speed>6</max_speed>

        <!-- PID tuning -->
        <left_steering_pid_gain>1500 0 1</left_steering_pid_gain>
        <left_steering_i_range>0 0</left_steering_i_range>
        <right_steering_pid_gain>1500 0 1</right_steering_pid_gain>
        <right_steering_i_range>0 0</right_steering_i_range>
        <linear_velocity_pid_gain>1000 0 1</linear_velocity_pid_gain>
        <linear_velocity_i_range>0 0</linear_velocity_i_range>

        <!-- output -->
        <publish_odom>true</publish_odom>
        <publish_odom_tf>true</publish_odom_tf>
        <publish_wheel_tf>true</publish_wheel_tf>
        <publish_distance>true</publish_distance>

        <odometry_frame>odom_demo</odometry_frame>
        <robot_base_frame>chassis</robot_base_frame>

      </plugin>
    
 <link name="hokuyo_link1">
            <pose>2.1 0 0.8 0 0 0</pose>
            <inertial>
               <inertia>
                  <ixx>1e-6</ixx>
                  <ixy>0</ixy>
                  <ixz>0</ixz>
                  <iyy>1e-6</iyy>
            <iyz>0</iyz>
            <izz>1e-6</izz>
         </inertia>
         <mass>1e-5</mass>
      </inertial>
      <collision name ="collision">
         <pose>0 0 0.5 0 0 0</pose>
         <geometry>
            <box>
               <size>0.1 0.1 0.1</size>
            </box>
         </geometry>
      </collision>
      <visual name="visual">
         <geometry>
            <mesh>
               <uri>model://hokuyo/meshes/hokuyo.dae</uri>
            </mesh>
         </geometry>
      </visual>
      <sensor name="laser1" type="gpu_ray">
         <pose>0.01 0 0.0175 0 -0 0</pose>
          <ray>
                 <scan>
                     <horizontal>
                           <samples>320</samples>
                          <resolution>5</resolution>
                          <min_angle>-0.50</min_angle>
                          <max_angle>0.50</max_angle>
                      </horizontal>
                   </scan>
                 <range>
                      <min>1</min>
                      <max>10</max>
                 </range>
              </ray>
         <plugin name="laser1" filename="libgazebo_ros_ray_sensor.so">
            <ros>
               <remapping>~/out:=scan1</remapping>
            </ros>
            
            <frame_name>laser_Frame</frame_name>
            <output_type>sensor_msgs/LaserScan</output_type>
         </plugin>
         <always_on>1</always_on>
         <update_rate>5</update_rate>
         <visualize>1</visualize>
      </sensor>
   </link>
   <joint name="hokuyo_joint" type="revolute">
      <parent>chassis</parent>
      <child>hokuyo_link1</child>
      <axis>
         <xyz>0 1 0</xyz>
         <limit>
            <upper>0</upper>
            <lower>0</lower>
         </limit>
      </axis>
   </joint>
    </model>

 <actor name="animated_box">
        <link name="link">
          <visual name="visual">
            <geometry>
              <box>
                <size>2 2 2</size>
              </box>
            </geometry>
          </visual>
        </link>
         <script>
          <loop>true</loop>
          <delay_start>0.000000</delay_start>
          <auto_start>true</auto_start>
           <trajectory id="0" type="square">
             <waypoint>
                <time>0.0</time>
                <pose>-22.4 38.7 0.3 0 0 0</pose>
             </waypoint>
             <waypoint>
                <time>1.0</time>
                <pose>-23.4 38.7 0.2 0 0 0</pose>
             </waypoint>
             <waypoint>
                <time>3.0</time>
                <pose>-24.4 38.7 0.2 0 0 0</pose>
             </waypoint>
             <waypoint>
                <time>4.0</time>
                <pose>-25.4 38.7 0.2 0 0 0</pose>
             </waypoint>
             <waypoint>
                <time>5.0</time>
                <pose>-26.4 38.7 0.2 0 0 0</pose>
             </waypoint>
             <waypoint>
                <time>6.0</time>
                <pose>-27.4 38.7 0.2 0 0 0</pose>
             </waypoint>
             <waypoint>
                <time>7.0</time>
                <pose>-28.4 38.7 0.2 0 0 0</pose>
             </waypoint>
             <waypoint>
                <time>8.0</time>
                <pose>-29.4 38.7 0.2 0 0 0</pose>
             </waypoint>
             <waypoint>
                <time>9.0</time>
                <pose>-30.4 38.7 0.2 0 0 0</pose>
             </waypoint>
             <waypoint>
                <time>10.0</time>
                <pose>-31.4 38.7 0.2 0 0 0</pose>
             </waypoint>
             <waypoint>
                <time>11.0</time>
                <pose>-32.4 38.7 0.2 0 0 0</pose>
             </waypoint>
             <waypoint>
                <time>12.0</time>
                <pose>-33.4 38.7 0.2 0 0 0</pose>
             </waypoint>
             <waypoint>
                <time>13.0</time>
                <pose>-34.4 38.7 0.2 0 0 0</pose>
             </waypoint>
             <waypoint>
                <time>14.0</time>
                <pose>-33.4 38.7 0.2 0 0 0</pose>
             </waypoint>
             <waypoint>
                <time>15.0</time>
                <pose>-32.4 38.7 0.2 0 0 0</pose>
             </waypoint>
             <waypoint>
                <time>16.0</time>
                <pose>-31.4 38.7 0.2 0 0 0</pose>
             </waypoint>
             <waypoint>
                <time>17.0</time>
                <pose>-30.4 38.7 0.2 0 0 0</pose>
             </waypoint>
             <waypoint>
                <time>18.0</time>
                <pose>-29.4 38.7 0.2 0 0 0</pose>
             </waypoint>
             <waypoint>
                <time>20.0</time>
                <pose>-28.4 38.7 0.2 0 0 0</pose>
             </waypoint>
             <waypoint>
                <time>21.0</time>
                <pose>-27.4 38.7 0.2 0 0 0</pose>
             </waypoint>
             <waypoint>
                <time>22.0</time>
                <pose>-26.4 38.7 0.2 0 0 0</pose>
             </waypoint>
             <waypoint>
                <time>23.0</time>
                <pose>-25.4 38.7 0.2 0 0 0</pose>
             </waypoint>
             <waypoint>
                <time>24.0</time>
                <pose>-24.4 38.7 0.2 0 0 0</pose>
             </waypoint>
             <waypoint>
                <time>25.0</time>
                <pose>-23.4 38.7 0.2 0 0 0</pose>
             </waypoint>
             <waypoint>
                <time>26.0</time>
                <pose>-22.4 38.7 0.2 0 0 0</pose>
             </waypoint>                                                                                                                                                                                                                                                       
          </trajectory>
        </script>
      </actor>
         

  <actor name="actor">
      <skin>
        <filename>walk.dae</filename>
      </skin>
      <animation name="walking">
        <filename>walk.dae</filename>
   <interpolate_x>true</interpolate_x>
      </animation>
      <script>
        <trajectory id="0" type="walking">
<waypoint>
  <time>0</time>
  <pose>0 -52 0.2 0 0 -1.5</pose>
</waypoint>

<waypoint>
  <time>0.2</time>
  <pose>0 -52.2 0.2 0 0 -1.5</pose>
</waypoint>

<waypoint>
  <time>0.4</time>
  <pose>0 -52.4 0.2 0 0 -1.5</pose>
</waypoint>

<waypoint>
  <time>0.6</time>
  <pose>0 -52.6 0.2 0 0 -1.5</pose>
</waypoint>

<waypoint>
  <time>0.8</time>
  <pose>0 -52.8 0.2 0 0 -1.5</pose>
</waypoint>

<waypoint>
  <time>1</time>
  <pose>0 -53 0.2 0 0 -1.5</pose>
</waypoint>

<waypoint>
  <time>1.2</time>
  <pose>0 -53.2 0.2 0 0 -1.5</pose>
</waypoint>

<waypoint>
  <time>1.4</time>
  <pose>0 -53.4 0.2 0 0 -1.5</pose>
</waypoint>

<waypoint>
  <time>1.6</time>
  <pose>0 -53.6 0.2 0 0 -1.5</pose>
</waypoint>

<waypoint>
  <time>1.8</time>
  <pose>0 -53.8 0.2 0 0 -1.5</pose>
</waypoint>

<waypoint>
  <time>2</time>
  <pose>0 -54 0.2 0 0 -1.5</pose>
</waypoint>

<waypoint>
  <time>2.2</time>
  <pose>0 -54.2 0.2 0 0 -1.5</pose>
</waypoint>

<waypoint>
  <time>2.4</time>
  <pose>0 -54.4 0.2 0 0 -1.5</pose>
</waypoint>

<waypoint>
  <time>2.6</time>
  <pose>0 -54.6 0.2 0 0 -1.5</pose>
</waypoint>

<waypoint>
  <time>2.8</time>
  <pose>0 -54.8 0.2 0 0 -1.5</pose>
</waypoint>

<waypoint>
  <time>3</time>
  <pose>0 -55 0.2 0 0 -1.5</pose>
</waypoint>

<waypoint>
  <time>3.2</time>
  <pose>0 -55.2 0.2 0 0 -1.5</pose>
</waypoint>

<waypoint>
  <time>3.4</time>
  <pose>0 -55.4 0.2 0 0 -1.5</pose>
</waypoint>

<waypoint>
  <time>3.6</time>
  <pose>0 -55.6 0.2 0 0 -1.5</pose>
</waypoint>

<waypoint>
  <time>3.8</time>
  <pose>0 -55.8 0.2 0 0 -1.5</pose>
</waypoint>

<waypoint>
  <time>4</time>
  <pose>0 -56 0.2 0 0 -1.5</pose>
</waypoint>

<waypoint>
  <time>4.2</time>
  <pose>0 -56.2 0.2 0 0 -1.5</pose>
</waypoint>

<waypoint>
  <time>4.4</time>
  <pose>0 -56.4 0.2 0 0 -1.5</pose>
</waypoint>

<waypoint>
  <time>4.6</time>
  <pose>0 -56.6 0.2 0 0 -1.5</pose>
</waypoint>

<waypoint>
  <time>4.8</time>
  <pose>0 -56.8 0.2 0 0 -1.5</pose>
</waypoint>

<waypoint>
  <time>5</time>
  <pose>0 -57 0.2 0 0 -1.5</pose>
</waypoint>

<waypoint>
  <time>5.2</time>
  <pose>0 -57.2 0.2 0 0 -1.5</pose>
</waypoint>

<waypoint>
  <time>5.4</time>
  <pose>0 -57.4 0.2 0 0 -1.5</pose>
</waypoint>

<waypoint>
  <time>5.6</time>
  <pose>0 -57.6 0.2 0 0 -1.5</pose>
</waypoint>

<waypoint>
  <time>5.8</time>
  <pose>0 -57.8 0.2 0 0 -1.5</pose>
</waypoint>

<waypoint>
  <time>6</time>
  <pose>0 -58 0.2 0 0 -1.5</pose>
</waypoint>

<waypoint>
  <time>6.2</time>
  <pose>0 -58.2 0.2 0 0 -1.5</pose>
</waypoint>

<waypoint>
  <time>6.4</time>
  <pose>0 -58.4 0.2 0 0 -1.5</pose>
</waypoint>

<waypoint>
  <time>6.6</time>
  <pose>0 -58.6 0.2 0 0 -1.5</pose>
</waypoint>

<waypoint>
  <time>6.8</time>
  <pose>0 -58.8 0.2 0 0 -1.5</pose>
</waypoint>

<waypoint>
  <time>7</time>
  <pose>0 -59 0.2 0 0 -1.5</pose>
</waypoint>

<waypoint>
  <time>7.2</time>
  <pose>0 -59.2 0.2 0 0 -1.5</pose>
</waypoint>

<waypoint>
  <time>7.4</time>
  <pose>0 -59.4 0.2 0 0 -1.5</pose>
</waypoint>

<waypoint>
  <time>7.6</time>
  <pose>0 -59.6 0.2 0 0 -1.5</pose>
</waypoint>

<waypoint>
  <time>7.8</time>
  <pose>0 -59.8 0.2 0 0 -1.5</pose>
</waypoint>

<waypoint>
  <time>8</time>
  <pose>0 -60 0.2 0 0 -1.5</pose>
</waypoint>

<waypoint>
  <time>8.2</time>
  <pose>0 -60.2 0.2 0 0 -1.5</pose>
</waypoint>

<waypoint>
  <time>8.4</time>
  <pose>0 -60.4 0.2 0 0 -1.5</pose>
</waypoint>

<waypoint>
  <time>8.6</time>
  <pose>0 -60.6 0.2 0 0 -1.5</pose>
</waypoint>

<waypoint>
  <time>8.8</time>
  <pose>0 -60.8 0.2 0 0 -1.5</pose>
</waypoint>

<waypoint>
  <time>9</time>
  <pose>0 -61 0.2 0 0 -1.5</pose>
</waypoint>

<waypoint>
  <time>9.2</time>
  <pose>0 -61.2 0.2 0 0 -1.5</pose>
</waypoint>

<waypoint>
  <time>9.4</time>
  <pose>0 -61.4 0.2 0 0 -1.5</pose>
</waypoint>

<waypoint>
  <time>9.6</time>
  <pose>0 -61.6 0.2 0 0 -1.5</pose>
</waypoint>

<waypoint>
  <time>9.8</time>
  <pose>0 -61.8 0.2 0 0 -1.5</pose>
</waypoint>
<waypoint>
  <time>10.0</time>
  <pose>0 -62 0.2 0 0 -1.5</pose>
</waypoint>

<waypoint>
  <time>10.2</time>
  <pose>0 -62 0.2 0 0 1.5</pose>
</waypoint>

<waypoint>
  <time>10.4</time>
  <pose>0 -61.8 0.2 0 0 1.5</pose>
</waypoint>

<waypoint>
  <time>10.6</time>
  <pose>0 -61.6 0.2 0 0 1.5</pose>
</waypoint>

<waypoint>
  <time>10.8</time>
  <pose>0 -61.4 0.2 0 0 1.5</pose>
</waypoint>

<waypoint>
  <time>11</time>
  <pose>0 -61.2 0.2 0 0 1.5</pose>
</waypoint>

<waypoint>
  <time>11.2</time>
  <pose>0 -61 0.2 0 0 1.5</pose>
</waypoint>

<waypoint>
  <time>11.4</time>
  <pose>0 -60.8 0.2 0 0 1.5</pose>
</waypoint>

<waypoint>
  <time>11.6</time>
  <pose>0 -60.6 0.2 0 0 1.5</pose>
</waypoint>

<waypoint>
  <time>11.8</time>
  <pose>0 -60.4 0.2 0 0 1.5</pose>
</waypoint>

<waypoint>
  <time>12</time>
  <pose>0 -60.2 0.2 0 0 1.5</pose>
</waypoint>

<waypoint>
  <time>12.2</time>
  <pose>0 -60 0.2 0 0 1.5</pose>
</waypoint>

<waypoint>
  <time>12.4</time>
  <pose>0 -59.8 0.2 0 0 1.5</pose>
</waypoint>

<waypoint>
  <time>12.6</time>
  <pose>0 -59.6 0.2 0 0 1.5</pose>
</waypoint>

<waypoint>
  <time>12.8</time>
  <pose>0 -59.4 0.2 0 0 1.5</pose>
</waypoint>

<waypoint>
  <time>13</time>
  <pose>0 -59.2 0.2 0 0 1.5</pose>
</waypoint>

<waypoint>
  <time>13.2</time>
  <pose>0 -59 0.2 0 0 1.5</pose>
</waypoint>

<waypoint>
  <time>13.4</time>
  <pose>0 -58.8 0.2 0 0 1.5</pose>
</waypoint>

<waypoint>
  <time>13.6</time>
  <pose>0 -58.6 0.2 0 0 1.5</pose>
</waypoint>

<waypoint>
  <time>13.8</time>
  <pose>0 -58.4 0.2 0 0 1.5</pose>
</waypoint>

<waypoint>
  <time>14</time>
  <pose>0 -58.2 0.2 0 0 1.5</pose>
</waypoint>

<waypoint>
  <time>14.2</time>
  <pose>0 -58 0.2 0 0 1.5</pose>
</waypoint>

<waypoint>
  <time>14.4</time>
  <pose>0 -57.8 0.2 0 0 1.5</pose>
</waypoint>

<waypoint>
  <time>14.6</time>
  <pose>0 -57.6 0.2 0 0 1.5</pose>
</waypoint>

<waypoint>
  <time>14.8</time>
  <pose>0 -57.4 0.2 0 0 1.5</pose>
</waypoint>

<waypoint>
  <time>15</time>
  <pose>0 -57.2 0.2 0 0 1.5</pose>
</waypoint>

<waypoint>
  <time>15.2</time>
  <pose>0 -57 0.2 0 0 1.5</pose>
</waypoint>

<waypoint>
  <time>15.4</time>
  <pose>0 -56.8 0.2 0 0 1.5</pose>
</waypoint>

<waypoint>
  <time>15.6</time>
  <pose>0 -56.6 0.2 0 0 1.5</pose>
</waypoint>

<waypoint>
  <time>15.8</time>
  <pose>0 -56.4 0.2 0 0 1.5</pose>
</waypoint>

<waypoint>
  <time>16</time>
  <pose>0 -56.2 0.2 0 0 1.5</pose>
</waypoint>

<waypoint>
  <time>16.2</time>
  <pose>0 -56 0.2 0 0 1.5</pose>
</waypoint>

<waypoint>
  <time>16.4</time>
  <pose>0 -55.8 0.2 0 0 1.5</pose>
</waypoint>

<waypoint>
  <time>16.6</time>
  <pose>0 -55.6 0.2 0 0 1.5</pose>
</waypoint>

<waypoint>
  <time>16.8</time>
  <pose>0 -55.4 0.2 0 0 1.5</pose>
</waypoint>

<waypoint>
  <time>17</time>
  <pose>0 -55.2 0.2 0 0 1.5</pose>
</waypoint>

<waypoint>
  <time>17.2</time>
  <pose>0 -55 0.2 0 0 1.5</pose>
</waypoint>

<waypoint>
  <time>17.4</time>
  <pose>0 -54.8 0.2 0 0 1.5</pose>
</waypoint>

<waypoint>
  <time>17.6</time>
  <pose>0 -54.6 0.2 0 0 1.5</pose>
</waypoint>

<waypoint>
  <time>17.8</time>
  <pose>0 -54.4 0.2 0 0 1.5</pose>
</waypoint>

<waypoint>
  <time>18</time>
  <pose>0 -54.2 0.2 0 0 1.5</pose>
</waypoint>

<waypoint>
  <time>18.2</time>
  <pose>0 -54 0.2 0 0 1.5</pose>
</waypoint>

<waypoint>
  <time>18.4</time>
  <pose>0 -53.8 0.2 0 0 1.5</pose>
</waypoint>

<waypoint>
  <time>18.6</time>
  <pose>0 -53.6 0.2 0 0 1.5</pose>
</waypoint>

<waypoint>
  <time>18.8</time>
  <pose>0 -53.4 0.2 0 0 1.5</pose>
</waypoint>

<waypoint>
  <time>19</time>
  <pose>0 -53.2 0.2 0 0 1.5</pose>
</waypoint>

<waypoint>
  <time>19.2</time>
  <pose>0 -53 0.2 0 0 1.5</pose>
</waypoint>

<waypoint>
  <time>19.4</time>
  <pose>0 -52.8 0.2 0 0 1.5</pose>
</waypoint>

<waypoint>
  <time>19.6</time>
  <pose>0 -52.6 0.2 0 0 1.5</pose>
</waypoint>

<waypoint>
  <time>19.8</time>
  <pose>0 -52.4 0.2 0 0 1.5</pose>
</waypoint>

<waypoint>
  <time>20</time>
  <pose>0 -52.2 0.2 0 0 1.5</pose>
</waypoint>

<waypoint>
  <time>20.2</time>
  <pose>0 -52 1 0 0 1.5</pose>
          </waypoint>       
        </trajectory>
      </script>
    </actor>

    

    <model name="up_road">
      <pose>-28.48 -11.5 -4.75 0.0 -0.08 -1.58</pose>
      <static>1</static>
      <link name="link">
        <collision name="collision">
          <geometry>
            <box>
              <size>10 10 10</size>
            </box>
          </geometry>
          <surface>
            <contact>
              <ode/>
            </contact>
          </surface>
        </collision>
        <visual name="visual">
          <geometry>
            <box>
              <size>10 10 10</size>
            </box>
          </geometry>
          <material>
            <script>
               <uri>file://media/materials/scripts/gazebo.material</uri>
               <name>Gazebo/Gray</name>  
            </script>
          </material>
        </visual>
      </link>
    </model>

      
    <model name="flat_road">
      <pose>-28.551 -18.5 -4.37 0.0 0.0 1.56</pose>
      <static>1</static>
      <link name="link">
        <collision name="collision">
          <geometry>
            <box>
              <size>5 10 10</size>
            </box>
          </geometry>
          <surface>
            <contact>
              <ode/>
            </contact>
          </surface>
        </collision>
        <visual name="visual">
          <geometry>
            <box>
              <size>5 10 10</size>
            </box>
          </geometry>
          <material>
            <script>
               <uri>file://media/materials/scripts/gazebo.material</uri>
               <name>Gazebo/Gray</name>  
            </script>
          </material>
        </visual>
      </link>
    </model>
    


    
    <model name="down_road">
      <pose>-28.61 -25.4 -4.75 0 0.08 -1.58</pose>
      <static>1</static>
      <link name="link">
        <collision name="collision">
          <geometry>
            <box>
              <size>10 10 10</size>
            </box>
          </geometry>
          <surface>
            <contact>
              <ode/>
            </contact>
          </surface>
        </collision>
        <visual name="visual">
          <geometry>
            <box>
              <size>10 10 10</size>
            </box>
          </geometry>
          <material>
            <script>
               <uri>file://media/materials/scripts/gazebo.material</uri>
               <name>Gazebo/Gray</name>  
            </script>
          </material>
        </visual>
      </link>
    </model>
 

<model name="road"> <!-- -28.5 -10.5 -4.55 0.0 -0.1 -1.58 -->
      <pose>-28.4 -8.5 0.47 0.0 0.10 1.57</pose>
      <static>1</static>
      <link name="road">
        <collision name="road_coll">
          <geometry>
            <box>
              <size>13 9.6 0.05</size>
            </box>
          </geometry>
          <surface>
            <contact>
              <ode/>
            </contact>
          </surface>
        </collision>
        <visual name="road_vis">
          <geometry>
            <box>
              <size>13 9 0.05</size>
            </box>
          </geometry>
          <material>
            <script>
              <uri> ./road.material </uri>  <!-- file://course.material -->
              <name>road</name>
            </script>
          </material>
        </visual>
      </link>
    </model>
    
    <model name="road2"> <!-- -28.5 -17.5 -4.08 0.0 0.0 1.56 -->
      <pose>-28.4 -17.4 1.1 0.0 0.0 1.57</pose>
      <static>1</static>
      <link name="road2">
        <collision name="road2_coll">
          <geometry>
            <box>
              <size>5.0 9.1 0.05</size>
            </box>
          </geometry>
          <surface>
            <contact>
              <ode/>
            </contact>
          </surface>
        </collision>
        <visual name="road2_vis">
          <geometry>
            <box>
              <size>5.0 9.2 0.05</size>
            </box>
          </geometry>
          <material>
            <script>
              <uri> ./road1.material </uri>  <!-- file://course.material -->
              <name>road1</name>
            </script>
          </material>
        </visual>
      </link>
    </model> 
    
    <model name="road3"> <!-- -28.5 -24.4 -4.55 0 0.1 -1.58 -->
      <pose>-28.4 -26.4 0.45 0.0 -0.1 1.583</pose>
      <static>1</static>
      <link name="road3">
        <collision name="road3_coll">
          <geometry>
            <box>
              <size>13 9 0.05</size>
            </box>
          </geometry>
          <surface>
            <contact>
              <ode/>
            </contact>
          </surface>
        </collision>
        <visual name="road3_vis">
          <geometry>
            <box>
              <size>13 9 0.05</size>
            </box>
          </geometry>
          <material>
            <script>
              <uri> ./road1.material </uri>  <!-- file://course.material -->
              <name>road1</name>
            </script>
          </material>
        </visual>
      </link>
    </model>

	

  </world>
</sdf>
